Failed to execute action: test_server()
Traceback (most recent call last):
  File "/home/limyreth/pyautomate/pyautomate/main.py", line 19, in <module>
    application.run()
  File "/home/limyreth/pyautomate/pyautomate/application.py", line 38, in run
    self._execute_path(dfa, options.exact)
  File "/home/limyreth/pyautomate/pyautomate/application.py", line 173, in _execute_path
    eval(action, vars(self._config))
  File "<string>", line 1, in <module>
  File "/home/limyreth/.texttest/tmp/tt.26Jun094521.5746/tt/multistate_automaton/partial/persisted_data_between_actions/second_action_fails/auto.py", line 30, in test_server
    raise Exception()
Exception
